Workbook

Sheet Executive_Dashboard
A1: Risk Dashboard — Executive Summary
A3: Company | E3: Risk Snapshot
A4: Company Name: | B4: ='Company_Profile'!B2 | E4: Safety Guardrail: | F4: =IFERROR(VLOOKUP("Subcontractor Guardrail Triggered",Summary!A:B,2,FALSE),"")
A5: Assessment ID: | B5: ='Company_Profile'!B5 | E5: Open Actions: | F5: =COUNTIF(Action_Register!O:O,"Open")
A6: Assessment Date: | B6: ='Company_Profile'!B6 | E6: Verified Actions: | F6: =COUNTIF(Action_Register!O:O,"Verified")
E7: Closed Actions: | F7: =COUNTIF(Action_Register!O:O,"Closed")
E8: Blocked Closures: | F8: =COUNTIF(Action_Register!AE:AE,"BLOCKED")
E9: Execution Momentum: | F9: =IFERROR(LOOKUP(2,1/(Outcome_Tracking!Q:Q<>""),Outcome_Tracking!Q:Q),"")
A11: Outcome Tracking (Most Recent)
A12: Most Recent Loss Ratio: | B12: =IFERROR(LOOKUP(2,1/(Outcome_Tracking!K:K<>""),Outcome_Tracking!K:K),"")
A13: Most Recent Trend: | B13: =IFERROR(LOOKUP(2,1/(Outcome_Tracking!M:M<>""),Outcome_Tracking!M:M),"")
A14: Guardrail Active at Checkpoint: | B14: =IFERROR(LOOKUP(2,1/(Outcome_Tracking!O:O<>""),Outcome_Tracking!O:O),"")
A16: Top Risks & Next Actions
A17: Blocking Actions (if any):
A18: Blocking Count: | B18: =COUNTIFS(Action_Register!K:K,"YES",Action_Register!O:O,"<>Closed",Action_Register!O:O,"<>")
A19: Critical Open Count: | B19: =COUNTIFS(Action_Register!J:J,"Critical",Action_Register!O:O,"Open")
A20: Next Step: | B20: ="Review Action_Plan tab and filter to Open + Critical + Blocking."

Sheet Company_Profile
A1: Company Profile
A2: Company Name | B2: Sample Insured
A3: Company Address
A4: Company Representative
A5: Assessment ID | B5: A-0001
A6: Assessment Date | B6: =TODAY()

Sheet Config
A1: Risk App Scoring Engine — Final Weights (Safety 40 / WC 20 / Fleet 40)
A3: Enter 1–5 in Responses. Overall score is calculated from global weights in Questions.
A5: Overall Rating Bands
A7: Min | B7: Max | C7: Rating
A8: 0 | B8: 54.999 | C8: High Risk
A9: 55 | B9: 69.999 | C9: Elevated Risk
A10: 70 | B10: 84.999 | C10: Moderate Risk
A11: 85 | B11: 100 | C11: Strong / Low Risk

Sheet Questions
A1: QuestionID | B1: Pillar | C1: Topic | D1: Question Text | E1: RespType | F1: Weight | G1: ScaleNotes | H1: Constraints
A2: SAF-01 | B2: Safety | C2: Policy Review & Leadership | D2: Is there a formal safety policy, how often is it reviewed, and how is executive leadership involved in supporting and enforcing safety expectations? | E2: Scale1to5 | F2: 0.04 | G2: 1=No formal review; leadership unclear. 2=Reviewed >24 months ago; limited/unclear leadership. 3=Reviewed within 12–24 months; some leadership participation. 4=Reviewed within last 12 months; defined leadership roles involved. 5=Reviewed within last 12 months; includes executive-level participation. | H2: Constraint: if not reviewed on a defined interval, cap at 3.
A3: SAF-02 | B3: Safety | C3: Training (Hire + Method + Verification) | D3: At what point do employees receive safety training, how often is it conducted, by what methods, and how is understanding or competency verified? | E3: Scale1to5 | F3: 0.08 | G3: 1=Infrequent/ad hoc; employees may work before training; passive; no verification. 2=Scheduled but employees may work before training; limited verification. 3=Training at/before time of hire + cadence; mostly classroom/online; limited verification. 4=Training at/before time of hire + routine cadence; hands-on/field; documented observation/coaching. 5=Training at/before time of hire + cadence AND triggers; verified via observation/coaching and follow-up. | H3: Constraint: if employees work before training, cap at 2.
A4: SAF-03 | B4: Safety | C4: Incidents & Near-Misses (System Fixes) | D4: How are safety incidents and near-misses investigated, how are deficiencies in safety management systems identified, and how are those deficiencies corrected? | E4: Scale1to5 | F4: 0.06 | G4: 1=Reactive; near-misses rarely reported; actions informal; no verification. 2=Documented but shallow; near-miss inconsistent; actions delayed/closed without verification. 3=Defined process for incidents+near-misses; owners/due dates; limited effectiveness verification. 4=Prompt structured investigations; system fixes implemented; follow-up verifies effectiveness. 5=Root-cause + risk prioritization; leadership reviews trends; effectiveness verified over time. | H4: Constraint: if near-misses not reviewed, cap at 2. If only employee blame, cap at 3.
A5: SAF-04 | B5: Safety | C5: Supervisor Observations & Coaching (System Focus) | D5: How do supervisors conduct safety observations, provide coaching, and address system-level contributors rather than placing blame solely on employees? | E5: Scale1to5 | F5: 0.08 | G5: 1=Rare/reactive or punitive; rule-violation focused; no follow-up. 2=Occasional and documented; mostly behavior-focused; limited escalation/system fixes. 3=Routine observations; some system issues; follow-up inconsistent. 4=Routine and system-focused; issues documented/escalated; actions verified. 5=Embedded practice; trend review; coaching drives system change; effectiveness verified. | H5: Constraint: if observations are primarily punitive/behavior-only, cap at 2.
A6: SAF-05 | B6: Safety | C6: Frontline Hazard Reporting (No Fear + Feedback) | D6: How do frontline employees report hazards and unsafe conditions without fear of reprisal, and how are those reports tracked, addressed, and communicated back? | E6: Scale1to5 | F6: 0.08 | G6: 1=Reporting unclear/limited; fear of discipline; little tracking/response. 2=Mechanism exists but low trust; inconsistent tracking/response; little feedback. 3=Clear reporting without fear; tracked/addressed; mostly reactive; participation not reinforced. 4=Actively encouraged; timely response; feedback provided; leadership supports reporting. 5=Embedded and reinforced; recognition/rewards; trends reviewed; employee input shapes improvements. | H6: Constraint: if reporting leads to blame/discipline, cap at 1. If no feedback loop, cap at 3.
A7: SAF-06 | B7: Safety | C7: Management Review & Action (Decisions + Follow-through) | D7: How does management review safety performance, what decisions are made as a result, and how is follow-through verified? | E7: Scale1to5 | F7: 0.06 | G7: 1=Rare/symbolic; reactive; no documented actions/verification. 2=Periodic but passive; mostly lagging metrics; limited/unresourced actions. 3=Regular structured reviews include some leading indicators; inconsistent follow-through. 4=Regular leading+lagging review; owners assigned; resources allocated; completion verified. 5=Strategic integration; decisions affect staffing/scheduling/capital; leadership accountable; effectiveness verified. | H7: Constraint: if lagging-only review, cap at 2. If actions not resourced, cap at 3.
A8: WC-01 | B8: WorkersComp | C8: Injury Reporting Timeliness & Accountability | D8: How are work-related injuries reported, who is responsible for reporting, and how is timely reporting enforced to preserve medical-only and return-to-work outcomes? | E8: Scale1to5 | F8: 0.04 | G8: 1=Expectations unclear; employees self-decide; supervisor role undefined; delays common. 2=Policy exists but weak communication/enforcement; delays frequent. 3=Roles defined; most injuries reported timely; monitoring/enforcement inconsistent. 4=All injuries required; supervisors escalate; timeliness tracked; delays addressed. 5=Immediate reporting embedded; metrics tracked and improved. | H8: Constraint: delayed reporting that prevents early medical intervention/RTW caps at 2.
A9: WC-02 | B9: WorkersComp | C9: Medical Direction (Clinics + Nurse Triage + Telemedicine) | D9: How is medical care directed following an injury, including use of nurse triage, telemedicine, and vetted occupational medical providers? | E9: Scale1to5 | F9: 0.04 | G9: 1=Uncontrolled entry; no direction/triage; restrictions unmanaged. 2=Informal/inconsistent direction; triage/telemed optional/rare. 3=Generally directed to occupational care/triage; limited coordination. 4=Directed to vetted clinics/triage/telemed as appropriate; coordinated; restrictions managed. 5=Integrated triage/telemed + vetted clinics; proactive restriction management; multi-state ready. | H9: Constraint: if employees choose initial providers without direction, cap at 2. For remote/multi-state, no triage/telemed caps at 3.
A10: WC-03 | B10: WorkersComp | C10: Return-to-Work Execution (Transitional Duty) | D10: How does the organization implement and manage return-to-work or transitional duty to reduce lost time and support recovery? | E10: Scale1to5 | F10: 0.04 | G10: 1=No RTW; off work until fully released. 2=RTW policy exists but avoided; options limited; lost-time common. 3=Options exist; used reactively; inconsistent by supervisor/location. 4=Early and consistent RTW; tasks pre-identified; restrictions accommodated. 5=Embedded RTW; supervisors accountable; outcomes tracked and improved. | H10: Constraint: if transitional duty not identified in advance, cap at 3. If supervisors resist restrictions, cap at 2.
A11: WC-04 | B11: WorkersComp | C11: Claim Oversight (Ownership to Closure) | D11: Who is responsible for managing workers’ compensation claims from initial report through closure, and how is progress monitored? | E11: Scale1to5 | F11: 0.03 | G11: 1=No internal ownership; carrier-only; minimal employee contact. 2=Informal ownership; inconsistent follow-up/communication. 3=Defined role exists; periodic oversight; inconsistent escalation. 4=Clear owner follows claims to closure; regular reviews; barriers addressed. 5=Proactive owner; early escalation; coordinated with carrier; timely resolution. | H11: Constraint: if no specific internal role follows claims to closure, cap at 2. Renewal-only review caps at 2.
A12: WC-05 | B12: WorkersComp | C12: Claims Review Intervals (Open Claims + Trends + Action) | D12: At what intervals are workers’ compensation claims reviewed, and how are open claims, trends, and corrective actions tracked? | E12: Scale1to5 | F12: 0.03 | G12: 1=No structured review; open claims drift. 2=Infrequent/renewal-only; little action. 3=Single cadence (e.g., quarterly); limited tracking of actions. 4=Multi-interval reviews (e.g., monthly open-claim + quarterly trends); actions assigned/tracked. 5=Dynamic cadence + triggers; drives closure and prevention; effectiveness monitored. | H12: Constraint: renewal-only caps at 2. If open claims not reviewed regularly to drive closure, cap at 3.
A13: WC-06 | B13: WorkersComp | C13: Employee Trust & Check-In Cadence | D13: Who maintains contact with injured employees, how often do check-ins occur, and how is trust maintained throughout the claim? | E13: Scale1to5 | F13: 0.02 | G13: 1=No owner/cadence; reactive contact only. 2=Informal/irregular check-ins; employees unsure who to contact. 3=Defined role; periodic check-ins but inconsistent. 4=Clear owner; defined regular check-ins; employees understand process. 5=Structured cadence + milestones; proactive, trust-centered engagement. | H13: Constraint: if no specific internal role owns check-ins, cap at 2. If no defined cadence, cap at 3.
... A21: FL-08 | B21: Fleet | C21: Management Review + Accountability (Fleet) | D21: How does leadership review fleet risk performance, assign accountability, and take action based on fleet risk metrics? | E21: Scale1to5 | F21: 0.01 | G21: 1=No management review; accountability unclear. 2=Infrequent/passive; little action. 3=Periodic review; limited ownership/follow-through. 4=Active review; named accountability; decisions change controls. 5=Embedded executive accountability; resources allocated; outcomes monitored. | H21: Constraint: if no defined cadence, cap at 2. If accountability diffused, cap at 3.

Sheet Responses
A1: Enter 1–5 in Response. Pillar, Weight, and scoring auto-calculate.
A2: AssessmentID | B2: Entity | C2: Date | D2: QuestionID | E2: Question Text | F2: Pillar | G2: Response | H2: RespType | I2: Weight | J2: NormScore | K2: WeightedPts | L2: Guidance
A3: =Company_Profile!$B$5 | B3: =Company_Profile!$B$2 | C3: =Company_Profile!$B$6 | D3: SAF-01 | E3: =IFERROR(INDEX(Questions!$D$2:$D$999,MATCH($D3,Questions!$A$2:$A$999,0)),"") | F3: =IFERROR(INDEX(Questions!$B$2:$B$999,MATCH($D3,Questions!$A$2:$A$999,0)),"") | H3: =IFERROR(INDEX(Questions!$E$2:$E$999,MATCH($D3,Questions!$A$2:$A$999,0)),"") | I3: =IFERROR(INDEX(Questions!$F$2:$F$999,MATCH($D3,Questions!$A$2:$A$999,0)),"") | J3: =IF(OR($G3="", $G3=0), "", ($G3-1)/4) | K3: =IF($J3="","",$J3*$I3) | L3: =IFERROR(INDEX(Questions!$G$2:$G$999,MATCH($D3,Questions!$A$2:$A$999,0)),"")
A4: =Company_Profile!$B$5 | B4: =Company_Profile!$B$2 | C4: =Company_Profile!$B$6 | D4: SAF-02 | E4: =IFERROR(INDEX(Questions!$D$2:$D$999,MATCH($D4,Questions!$A$2:$A$999,0)),"") | F4: =IFERROR(INDEX(Questions!$B$2:$B$999,MATCH($D4,Questions!$A$2:$A$999,0)),"") | H4: =IFERROR(INDEX(Questions!$E$2:$E$999,MATCH($D4,Questions!$A$2:$A$999,0)),"") | I4: =IFERROR(INDEX(Questions!$F$2:$F$999,MATCH($D4,Questions!$A$2:$A$999,0)),"") | J4: =IF(OR($G4="", $G4=0), "", ($G4-1)/4) | K4: =IF($J4="","",$J4*$I4) | L4: =IFERROR(INDEX(Questions!$G$2:$G$999,MATCH($D4,Questions!$A$2:$A$999,0)),"")
A5: =Company_Profile!$B$5 | B5: =Company_Profile!$B$2 | C5: =Company_Profile!$B$6 | D5: SAF-03 | E5: =IFERROR(INDEX(Questions!$D$2:$D$999,MATCH($D5,Questions!$A$2:$A$999,0)),"") | F5: =IFERROR(INDEX(Questions!$B$2:$B$999,MATCH($D5,Questions!$A$2:$A$999,0)),"") | H5: =IFERROR(INDEX(Questions!$E$2:$E$999,MATCH($D5,Questions!$A$2:$A$999,0)),"") | I5: =IFERROR(INDEX(Questions!$F$2:$F$999,MATCH($D5,Questions!$A$2:$A$999,0)),"") | J5: =IF(OR($G5="", $G5=0), "", ($G5-1)/4) | K5: =IF($J5="","",$J5*$I5) | L5: =IFERROR(INDEX(Questions!$G$2:$G$999,MATCH($D5,Questions!$A$2:$A$999,0)),"")
A6: =Company_Profile!$B$5 | B6: =Company_Profile!$B$2 | C6: =Company_Profile!$B$6 | D6: SAF-04 | E6: =IFERROR(INDEX(Questions!$D$2:$D$999,MATCH($D6,Questions!$A$2:$A$999,0)),"") | F6: =IFERROR(INDEX(Questions!$B$2:$B$999,MATCH($D6,Questions!$A$2:$A$999,0)),"") | H6: =IFERROR(INDEX(Questions!$E$2:$E$999,MATCH($D6,Questions!$A$2:$A$999,0)),"") | I6: =IFERROR(INDEX(Questions!$F$2:$F$999,MATCH($D6,Questions!$A$2:$A$999,0)),"") | J6: =IF(OR($G6="", $G6=0), "", ($G6-1)/4) | K6: =IF($J6="","",$J6*$I6) | L6: =IFERROR(INDEX(Questions!$G$2:$G$999,MATCH($D6,Questions!$A$2:$A$999,0)),"")
A7: =Company_Profile!$B$5 | B7: =Company_Profile!$B$2 | C7: =Company_Profile!$B$6 | D7: SAF-05 | E7: =IFERROR(INDEX(Questions!$D$2:$D$999,MATCH($D7,Questions!$A$2:$A$999,0)),"") | F7: =IFERROR(INDEX(Questions!$B$2:$B$999,MATCH($D7,Questions!$A$2:$A$999,0)),"") | H7: =IFERROR(INDEX(Questions!$E$2:$E$999,MATCH($D7,Questions!$A$2:$A$999,0)),"") | I7: =IFERROR(INDEX(Questions!$F$2:$F$999,MATCH($D7,Questions!$A$2:$A$999,0)),"") | J7: =IF(OR($G7="", $G7=0), "", ($G7-1)/4) | K7: =IF($J7="","",$J7*$I7) | L7: =IFERROR(INDEX(Questions!$G$2:$G$999,MATCH($D7,Questions!$A$2:$A$999,0)),"")
A8: =Company_Profile!$B$5 | B8: =Company_Profile!$B$2 | C8: =Company_Profile!$B$6 | D8: SAF-06 | E8: =IFERROR(INDEX(Questions!$D$2:$D$999,MATCH($D8,Questions!$A$2:$A$999,0)),"") | F8: =IFERROR(INDEX(Questions!$B$2:$B$999,MATCH($D8,Questions!$A$2:$A$999,0)),"") | H8: =IFERROR(INDEX(Questions!$E$2:$E$999,MATCH($D8,Questions!$A$2:$A$999,0)),"") | I8: =IFERROR(INDEX(Questions!$F$2:$F$999,MATCH($D8,Questions!$A$2:$A$999,0)),"") | J8: =IF(OR($G8="", $G8=0), "", ($G8-1)/4) | K8: =IF($J8="","",$J8*$I8) | L8: =IFERROR(INDEX(Questions!$G$2:$G$999,MATCH($D8,Questions!$A$2:$A$999,0)),"")
A9: =Company_Profile!$B$5 | B9: =Company_Profile!$B$2 | C9: =Company_Profile!$B$6 | D9: WC-01 | E9: =IFERROR(INDEX(Questions!$D$2:$D$999,MATCH($D9,Questions!$A$2:$A$999,0)),"") | F9: =IFERROR(INDEX(Questions!$B$2:$B$999,MATCH($D9,Questions!$A$2:$A$999,0)),"") | H9: =IFERROR(INDEX(Questions!$E$2:$E$999,MATCH($D9,Questions!$A$2:$A$999,0)),"") | I9: =IFERROR(INDEX(Questions!$F$2:$F$999,MATCH($D9,Questions!$A$2:$A$999,0)),"") | J9: =IF(OR($G9="", $G9=0), "", ($G9-1)/4) | K9: =IF($J9="","",$J9*$I9) | L9: =IFERROR(INDEX(Questions!$G$2:$G$999,MATCH($D9,Questions!$A$2:$A$999,0)),"")
A10: =Company_Profile!$B$5 | B10: =Company_Profile!$B$2 | C10: =Company_Profile!$B$6 | D10: WC-02 | E10: =IFERROR(INDEX(Questions!$D$2:$D$999,MATCH($D10,Questions!$A$2:$A$999,0)),"") | F10: =IFERROR(INDEX(Questions!$B$2:$B$999,MATCH($D10,Questions!$A$2:$A$999,0)),"") | H10: =IFERROR(INDEX(Questions!$E$2:$E$999,MATCH($D10,Questions!$A$2:$A$999,0)),"") | I10: =IFERROR(INDEX(Questions!$F$2:$F$999,MATCH($D10,Questions!$A$2:$A$999,0)),"") | J10: =IF(OR($G10="", $G10=0), "", ($G10-1)/4) | K10: =IF($J10="","",$J10*$I10) | L10: =IFERROR(INDEX(Questions!$G$2:$G$999,MATCH($D10,Questions!$A$2:$A$999,0)),"")
A11: =Company_Profile!$B$5 | B11: =Company_Profile!$B$2 | C11: =Company_Profile!$B$6 | D11: WC-03 | E11: =IFERROR(INDEX(Questions!$D$2:$D$999,MATCH($D11,Questions!$A$2:$A$999,0)),"") | F11: =IFERROR(INDEX(Questions!$B$2:$B$999,MATCH($D11,Questions!$A$2:$A$999,0)),"") | H11: =IFERROR(INDEX(Questions!$E$2:$E$999,MATCH($D11,Questions!$A$2:$A$999,0)),"") | I11: =IFERROR(INDEX(Questions!$F$2:$F$999,MATCH($D11,Questions!$A$2:$A$999,0)),"") | J11: =IF(OR($G11="", $G11=0), "", ($G11-1)/4) | K11: =IF($J11="","",$J11*$I11) | L11: =IFERROR(INDEX(Questions!$G$2:$G$999,MATCH($D11,Questions!$A$2:$A$999,0)),"")
A12: =Company_Profile!$B$5 | B12: =Company_Profile!$B$2 | C12: =Company_Profile!$B$6 | D12: WC-04 | E12: =IFERROR(INDEX(Questions!$D$2:$D$999,MATCH($D12,Questions!$A$2:$A$999,0)),"") | F12: =IFERROR(INDEX(Questions!$B$2:$B$999,MATCH($D12,Questions!$A$2:$A$999,0)),"") | H12: =IFERROR(INDEX(Questions!$E$2:$E$999,MATCH($D12,Questions!$A$2:$A$999,0)),"") | I12: =IFERROR(INDEX(Questions!$F$2:$F$999,MATCH($D12,Questions!$A$2:$A$999,0)),"") | J12: =IF(OR($G12="", $G12=0), "", ($G12-1)/4) | K12: =IF($J12="","",$J12*$I12) | L12: =IFERROR(INDEX(Questions!$G$2:$G$999,MATCH($D12,Questions!$A$2:$A$999,0)),"")
A13: =Company_Profile!$B$5 | B13: =Company_Profile!$B$2 | C13: =Company_Profile!$B$6 | D13: WC-05 | E13: =IFERROR(INDEX(Questions!$D$2:$D$999,MATCH($D13,Questions!$A$2:$A$999,0)),"") | F13: =IFERROR(INDEX(Questions!$B$2:$B$999,MATCH($D13,Questions!$A$2:$A$999,0)),"") | H13: =IFERROR(INDEX(Questions!$E$2:$E$999,MATCH($D13,Questions!$A$2:$A$999,0)),"") | I13: =IFERROR(INDEX(Questions!$F$2:$F$999,MATCH($D13,Questions!$A$2:$A$999,0)),"") | J13: =IF(OR($G13="", $G13=0), "", ($G13-1)/4) | K13: =IF($J13="","",$J13*$I13) | L13: =IFERROR(INDEX(Questions!$G$2:$G$999,MATCH($D13,Questions!$A$2:$A$999,0)),"")
A14: =Company_Profile!$B$5 | B14: =Company_Profile!$B$2 | C14: =Company_Profile!$B$6 | D14: WC-06 | E14: =IFERROR(INDEX(Questions!$D$2:$D$999,MATCH($D14,Questions!$A$2:$A$999,0)),"") | F14: =IFERROR(INDEX(Questions!$B$2:$B$999,MATCH($D14,Questions!$A$2:$A$999,0)),"") | H14: =IFERROR(INDEX(Questions!$E$2:$E$999,MATCH($D14,Questions!$A$2:$A$999,0)),"") | I14: =IFERROR(INDEX(Questions!$F$2:$F$999,MATCH($D14,Questions!$A$2:$A$999,0)),"") | J14: =IF(OR($G14="", $G14=0), "", ($G14-1)/4) | K14: =IF($J14="","",$J14*$I14) | L14: =IFERROR(INDEX(Questions!$G$2:$G$999,MATCH($D14,Questions!$A$2:$A$999,0)),"")
... A22: =Company_Profile!$B$5 | B22: =Company_Profile!$B$2 | C22: =Company_Profile!$B$6 | D22: FL-08 | E22: =IFERROR(INDEX(Questions!$D$2:$D$999,MATCH($D22,Questions!$A$2:$A$999,0)),"") | F22: =IFERROR(INDEX(Questions!$B$2:$B$999,MATCH($D22,Questions!$A$2:$A$999,0)),"") | H22: =IFERROR(INDEX(Questions!$E$2:$E$999,MATCH($D22,Questions!$A$2:$A$999,0)),"") | I22: =IFERROR(INDEX(Questions!$F$2:$F$999,MATCH($D22,Questions!$A$2:$A$999,0)),"") | J22: =IF(OR($G22="", $G22=0), "", ($G22-1)/4) | K22: =IF($J22="","",$J22*$I22) | L22: =IFERROR(INDEX(Questions!$G$2:$G$999,MATCH($D22,Questions!$A$2:$A$999,0)),"")

Sheet Summary
A1: Assessment Summary
A3: Assessment ID | B3: =Company_Profile!$B$5 | D3: TotalQuestions | E3: 20
A4: Entity | B4: =Company_Profile!$B$2
A5: Date | B5: =Company_Profile!$B$6
A7: Completion % | B7: =IFERROR(ROUND(100*COUNT(Responses!$G$3:$G$999)/$E$3,0),0)
A8: Overall Score (0-100) | B8: =IF(COUNT(Responses!$G$3:$G$999)<$E$3,"",ROUND(100*SUM(Responses!$K$3:$K$999),1))
A9: Overall Rating | B9: =IF(B8="","",INDEX(Config!$C$8:$C$11, MATCH(B8, Config!$A$8:$A$11, 1)))
A11: Pillar Scores
A12: Pillar | B12: Score (0-100) | C12: Weight Share
A13: Safety | B13: =IF($C13=0,"",ROUND(100*SUMIF(Responses!$F$3:$F$999,"Safety",Responses!$K$3:$K$999)/$C13,1)) | C13: 0.4
A14: WorkersComp | B14: =IF($C14=0,"",ROUND(100*SUMIF(Responses!$F$3:$F$999,"WorkersComp",Responses!$K$3:$K$999)/$C14,1)) | C14: 0.2
A15: Fleet | B15: =IF($C15=0,"",ROUND(100*SUMIF(Responses!$F$3:$F$999,"Fleet",Responses!$K$3:$K$999)/$C15,1)) | C15: 0.4
A17: Question-Level Detail
A18: QuestionID | B18: Pillar | C18: Topic | D18: Weight | E18: Response | F18: NormScore | G18: WeightedPts
A19: SAF-01 | B19: =IFERROR(INDEX(Questions!$B$2:$B$999,MATCH(A19,Questions!$A$2:$A$999,0)),"") | C19: =IFERROR(INDEX(Questions!$C$2:$C$999,MATCH(A19,Questions!$A$2:$A$999,0)),"") | D19: =IFERROR(INDEX(Questions!$E$2:$E$999,MATCH(A19,Questions!$A$2:$A$999,0)),0) | E19: =IFERROR(INDEX(Responses!$G$3:$G$999,MATCH($A19,Responses!$D$3:$D$999,0)),"") | F19: =IFERROR(INDEX(Responses!$J$3:$J$999,MATCH($A19,Responses!$D$3:$D$999,0)),"") | G19: =IFERROR(INDEX(Responses!$K$3:$K$999,MATCH($A19,Responses!$D$3:$D$999,0)),"")
A20: Safety Pillar Score (Adjusted) | B20: =IF(Subcontractor_SubScore!C3<=2,MIN(B19,'Score Interpretation'!B3),AVERAGE(B15:B19)) | C20: =IFERROR(INDEX(Questions!$C$2:$C$999,MATCH(A20,Questions!$A$2:$A$999,0)),"") | D20: =IFERROR(INDEX(Questions!$E$2:$E$999,MATCH(A20,Questions!$A$2:$A$999,0)),0) | E20: =IFERROR(INDEX(Responses!$G$3:$G$999,MATCH($A20,Responses!$D$3:$D$999,0)),"") | F20: =IFERROR(INDEX(Responses!$J$3:$J$999,MATCH($A20,Responses!$D$3:$D$999,0)),"") | G20: =IFERROR(INDEX(Responses!$K$3:$K$999,MATCH($A20,Responses!$D$3:$D$999,0)),"")
A21: Subcontractor Guardrail Triggered | B21: =IF(Subcontractor_SubScore!C3<=2,"YES","NO") | C21: =IFERROR(INDEX(Questions!$C$2:$C$999,MATCH(A21,Questions!$A$2:$A$999,0)),"") | D21: =IFERROR(INDEX(Questions!$E$2:$E$999,MATCH(A21,Questions!$A$2:$A$999,0)),0) | E21: =IFERROR(INDEX(Responses!$G$3:$G$999,MATCH($A21,Responses!$D$3:$D$999,0)),"") | F21: =IFERROR(INDEX(Responses!$J$3:$J$999,MATCH($A21,Responses!$D$3:$D$999,0)),"") | G21: =IFERROR(INDEX(Responses!$K$3:$K$999,MATCH($A21,Responses!$D$3:$D$999,0)),"")
A22: SAF-04 | B22: =IFERROR(INDEX(Questions!$B$2:$B$999,MATCH(A22,Questions!$A$2:$A$999,0)),"") | C22: =IFERROR(INDEX(Questions!$C$2:$C$999,MATCH(A22,Questions!$A$2:$A$999,0)),"") | D22: =IFERROR(INDEX(Questions!$E$2:$E$999,MATCH(A22,Questions!$A$2:$A$999,0)),0) | E22: =IFERROR(INDEX(Responses!$G$3:$G$999,MATCH($A22,Responses!$D$3:$D$999,0)),"") | F22: =IFERROR(INDEX(Responses!$J$3:$J$999,MATCH($A22,Responses!$D$3:$D$999,0)),"") | G22: =IFERROR(INDEX(Responses!$K$3:$K$999,MATCH($A22,Responses!$D$3:$D$999,0)),"")
A23: SAF-05 | B23: =IFERROR(INDEX(Questions!$B$2:$B$999,MATCH(A23,Questions!$A$2:$A$999,0)),"") | C23: =IFERROR(INDEX(Questions!$C$2:$C$999,MATCH(A23,Questions!$A$2:$A$999,0)),"") | D23: =IFERROR(INDEX(Questions!$E$2:$E$999,MATCH(A23,Questions!$A$2:$A$999,0)),0) | E23: =IFERROR(INDEX(Responses!$G$3:$G$999,MATCH($A23,Responses!$D$3:$D$999,0)),"") | F23: =IFERROR(INDEX(Responses!$J$3:$J$999,MATCH($A23,Responses!$D$3:$D$999,0)),"") | G23: =IFERROR(INDEX(Responses!$K$3:$K$999,MATCH($A23,Responses!$D$3:$D$999,0)),"")
A24: SAF-06 | B24: =IFERROR(INDEX(Questions!$B$2:$B$999,MATCH(A24,Questions!$A$2:$A$999,0)),"") | C24: =IFERROR(INDEX(Questions!$C$2:$C$999,MATCH(A24,Questions!$A$2:$A$999,0)),"") | D24: =IFERROR(INDEX(Questions!$E$2:$E$999,MATCH(A24,Questions!$A$2:$A$999,0)),0) | E24: =IFERROR(INDEX(Responses!$G$3:$G$999,MATCH($A24,Responses!$D$3:$D$999,0)),"") | F24: =IFERROR(INDEX(Responses!$J$3:$J$999,MATCH($A24,Responses!$D$3:$D$999,0)),"") | G24: =IFERROR(INDEX(Responses!$K$3:$K$999,MATCH($A24,Responses!$D$3:$D$999,0)),"")
A25: WC-01 | B25: =IFERROR(INDEX(Questions!$B$2:$B$999,MATCH(A25,Questions!$A$2:$A$999,0)),"") | C25: =IFERROR(INDEX(Questions!$C$2:$C$999,MATCH(A25,Questions!$A$2:$A$999,0)),"") | D25: =IFERROR(INDEX(Questions!$E$2:$E$999,MATCH(A25,Questions!$A$2:$A$999,0)),0) | E25: =IFERROR(INDEX(Responses!$G$3:$G$999,MATCH($A25,Responses!$D$3:$D$999,0)),"") | F25: =IFERROR(INDEX(Responses!$J$3:$J$999,MATCH($A25,Responses!$D$3:$D$999,0)),"") | G25: =IFERROR(INDEX(Responses!$K$3:$K$999,MATCH($A25,Responses!$D$3:$D$999,0)),"")
A26: WC-02 | B26: =IFERROR(INDEX(Questions!$B$2:$B$999,MATCH(A26,Questions!$A$2:$A$999,0)),"") | C26: =IFERROR(INDEX(Questions!$C$2:$C$999,MATCH(A26,Questions!$A$2:$A$999,0)),"") | D26: =IFERROR(INDEX(Questions!$E$2:$E$999,MATCH(A26,Questions!$A$2:$A$999,0)),0) | E26: =IFERROR(INDEX(Responses!$G$3:$G$999,MATCH($A26,Responses!$D$3:$D$999,0)),"") | F26: =IFERROR(INDEX(Responses!$J$3:$J$999,MATCH($A26,Responses!$D$3:$D$999,0)),"") | G26: =IFERROR(INDEX(Responses!$K$3:$K$999,MATCH($A26,Responses!$D$3:$D$999,0)),"")
A27: WC-03 | B27: =IFERROR(INDEX(Questions!$B$2:$B$999,MATCH(A27,Questions!$A$2:$A$999,0)),"") | C27: =IFERROR(INDEX(Questions!$C$2:$C$999,MATCH(A27,Questions!$A$2:$A$999,0)),"") | D27: =IFERROR(INDEX(Questions!$E$2:$E$999,MATCH(A27,Questions!$A$2:$A$999,0)),0) | E27: =IFERROR(INDEX(Responses!$G$3:$G$999,MATCH($A27,Responses!$D$3:$D$999,0)),"") | F27: =IFERROR(INDEX(Responses!$J$3:$J$999,MATCH($A27,Responses!$D$3:$D$999,0)),"") | G27: =IFERROR(INDEX(Responses!$K$3:$K$999,MATCH($A27,Responses!$D$3:$D$999,0)),"")
A28: WC-04 | B28: =IFERROR(INDEX(Questions!$B$2:$B$999,MATCH(A28,Questions!$A$2:$A$999,0)),"") | C28: =IFERROR(INDEX(Questions!$C$2:$C$999,MATCH(A28,Questions!$A$2:$A$999,0)),"") | D28: =IFERROR(INDEX(Questions!$E$2:$E$999,MATCH(A28,Questions!$A$2:$A$999,0)),0) | E28: =IFERROR(INDEX(Responses!$G$3:$G$999,MATCH($A28,Responses!$D$3:$D$999,0)),"") | F28: =IFERROR(INDEX(Responses!$J$3:$J$999,MATCH($A28,Responses!$D$3:$D$999,0)),"") | G28: =IFERROR(INDEX(Responses!$K$3:$K$999,MATCH($A28,Responses!$D$3:$D$999,0)),"")
A29: WC-05 | B29: =IFERROR(INDEX(Questions!$B$2:$B$999,MATCH(A29,Questions!$A$2:$A$999,0)),"") | C29: =IFERROR(INDEX(Questions!$C$2:$C$999,MATCH(A29,Questions!$A$2:$A$999,0)),"") | D29: =IFERROR(INDEX(Questions!$E$2:$E$999,MATCH(A29,Questions!$A$2:$A$999,0)),0) | E29: =IFERROR(INDEX(Responses!$G$3:$G$999,MATCH($A29,Responses!$D$3:$D$999,0)),"") | F29: =IFERROR(INDEX(Responses!$J$3:$J$999,MATCH($A29,Responses!$D$3:$D$999,0)),"") | G29: =IFERROR(INDEX(Responses!$K$3:$K$999,MATCH($A29,Responses!$D$3:$D$999,0)),"")
A30: WC-06 | B30: =IFERROR(INDEX(Questions!$B$2:$B$999,MATCH(A30,Questions!$A$2:$A$999,0)),"") | C30: =IFERROR(INDEX(Questions!$C$2:$C$999,MATCH(A30,Questions!$A$2:$A$999,0)),"") | D30: =IFERROR(INDEX(Questions!$E$2:$E$999,MATCH(A30,Questions!$A$2:$A$999,0)),0) | E30: =IFERROR(INDEX(Responses!$G$3:$G$999,MATCH($A30,Responses!$D$3:$D$999,0)),"") | F30: =IFERROR(INDEX(Responses!$J$3:$J$999,MATCH($A30,Responses!$D$3:$D$999,0)),"") | G30: =IFERROR(INDEX(Responses!$K$3:$K$999,MATCH($A30,Responses!$D$3:$D$999,0)),"")
A31: FL-01 | B31: =IFERROR(INDEX(Questions!$B$2:$B$999,MATCH(A31,Questions!$A$2:$A$999,0)),"") | C31: =IFERROR(INDEX(Questions!$C$2:$C$999,MATCH(A31,Questions!$A$2:$A$999,0)),"") | D31: =IFERROR(INDEX(Questions!$E$2:$E$999,MATCH(A31,Questions!$A$2:$A$999,0)),0) | E31: =IFERROR(INDEX(Responses!$G$3:$G$999,MATCH($A31,Responses!$D$3:$D$999,0)),"") | F31: =IFERROR(INDEX(Responses!$J$3:$J$999,MATCH($A31,Responses!$D$3:$D$999,0)),"") | G31: =IFERROR(INDEX(Responses!$K$3:$K$999,MATCH($A31,Responses!$D$3:$D$999,0)),"")
A32: FL-02 | B32: =IFERROR(INDEX(Questions!$B$2:$B$999,MATCH(A32,Questions!$A$2:$A$999,0)),"") | C32: =IFERROR(INDEX(Questions!$C$2:$C$999,MATCH(A32,Questions!$A$2:$A$999,0)),"") | D32: =IFERROR(INDEX(Questions!$E$2:$E$999,MATCH(A32,Questions!$A$2:$A$999,0)),0) | E32: =IFERROR(INDEX(Responses!$G$3:$G$999,MATCH($A32,Responses!$D$3:$D$999,0)),"") | F32: =IFERROR(INDEX(Responses!$J$3:$J$999,MATCH($A32,Responses!$D$3:$D$999,0)),"") | G32: =IFERROR(INDEX(Responses!$K$3:$K$999,MATCH($A32,Responses!$D$3:$D$999,0)),"")
A33: FL-03 | B33: =IFERROR(INDEX(Questions!$B$2:$B$999,MATCH(A33,Questions!$A$2:$A$999,0)),"") | C33: =IFERROR(INDEX(Questions!$C$2:$C$999,MATCH(A33,Questions!$A$2:$A$999,0)),"") | D33: =IFERROR(INDEX(Questions!$E$2:$E$999,MATCH(A33,Questions!$A$2:$A$999,0)),0) | E33: =IFERROR(INDEX(Responses!$G$3:$G$999,MATCH($A33,Responses!$D$3:$D$999,0)),"") | F33: =IFERROR(INDEX(Responses!$J$3:$J$999,MATCH($A33,Responses!$D$3:$D$999,0)),"") | G33: =IFERROR(INDEX(Responses!$K$3:$K$999,MATCH($A33,Responses!$D$3:$D$999,0)),"")
... A38: FL-08 | B38: =IFERROR(INDEX(Questions!$B$2:$B$999,MATCH(A38,Questions!$A$2:$A$999,0)),"") | C38: =IFERROR(INDEX(Questions!$C$2:$C$999,MATCH(A38,Questions!$A$2:$A$999,0)),"") | D38: =IFERROR(INDEX(Questions!$E$2:$E$999,MATCH(A38,Questions!$A$2:$A$999,0)),0) | E38: =IFERROR(INDEX(Responses!$G$3:$G$999,MATCH($A38,Responses!$D$3:$D$999,0)),"") | F38: =IFERROR(INDEX(Responses!$J$3:$J$999,MATCH($A38,Responses!$D$3:$D$999,0)),"") | G38: =IFERROR(INDEX(Responses!$K$3:$K$999,MATCH($A38,Responses!$D$3:$D$999,0)),"")

Sheet Question Guide
A1: Risk App – Question Guide & Scoring Intent
A3: This worksheet explains the intent behind each question and how to score it. Use this guide to ensure scoring reflects actual practices, not written policies alone.
A4: Question ID | B4: Pillar | C4: Topic | D4: Why This Matters | E4: What Good Looks Like (High Score) | F4: Common Scoring Pitfalls | G4: Key Scoring Notes
A6: SAF-01 | B6: Safety | C6: Policy Review & Leadership | D6: Measures whether this control actively reduces risk and influences behavior, not just whether a policy or process exists. | E6: Practices are consistent, documented, owned by leadership or supervisors, and verified through action, follow-up, or outcomes. | F6: Scoring based on written policy only; assuming responsibility is handled elsewhere; counting infrequent or reactive actions as mature practices. | G6: Constraint: if not reviewed on a defined interval, cap at 3.
A7: SAF-02 | B7: Safety | C7: Training (Hire + Method + Verification) | D7: Measures whether this control actively reduces risk and influences behavior, not just whether a policy or process exists. | E7: Practices are consistent, documented, owned by leadership or supervisors, and verified through action, follow-up, or outcomes. | F7: Scoring based on written policy only; assuming responsibility is handled elsewhere; counting infrequent or reactive actions as mature practices. | G7: Constraint: if employees work before training, cap at 2.
A8: SAF-03 | B8: Safety | C8: Incidents & Near-Misses (System Fixes) | D8: Measures whether this control actively reduces risk and influences behavior, not just whether a policy or process exists. | E8: Practices are consistent, documented, owned by leadership or supervisors, and verified through action, follow-up, or outcomes. | F8: Scoring based on written policy only; assuming responsibility is handled elsewhere; counting infrequent or reactive actions as mature practices. | G8: Constraint: if near-misses not reviewed, cap at 2. If only employee blame, cap at 3.
A9: SAF-04 | B9: Safety | C9: Supervisor Observations & Coaching (System Focus) | D9: Measures whether this control actively reduces risk and influences behavior, not just whether a policy or process exists. | E9: Practices are consistent, documented, owned by leadership or supervisors, and verified through action, follow-up, or outcomes. | F9: Scoring based on written policy only; assuming responsibility is handled elsewhere; counting infrequent or reactive actions as mature practices. | G9: Constraint: if observations are primarily punitive/behavior-only, cap at 2.
A10: SAF-05 | B10: Safety | C10: Frontline Hazard Reporting (No Fear + Feedback) | D10: Measures whether this control actively reduces risk and influences behavior, not just whether a policy or process exists. | E10: Practices are consistent, documented, owned by leadership or supervisors, and verified through action, follow-up, or outcomes. | F10: Scoring based on written policy only; assuming responsibility is handled elsewhere; counting infrequent or reactive actions as mature practices. | G10: Constraint: if reporting leads to blame/discipline, cap at 1. If no feedback loop, cap at 3.
A11: SAF-06 | B11: Safety | C11: Management Review & Action (Decisions + Follow-through) | D11: Measures whether this control actively reduces risk and influences behavior, not just whether a policy or process exists. | E11: Practices are consistent, documented, owned by leadership or supervisors, and verified through action, follow-up, or outcomes. | F11: Scoring based on written policy only; assuming responsibility is handled elsewhere; counting infrequent or reactive actions as mature practices. | G11: Constraint: if lagging-only review, cap at 2. If actions not resourced, cap at 3.
A12: WC-01 | B12: WorkersComp | C12: Injury Reporting Timeliness & Accountability | D12: Measures whether this control actively reduces risk and influences behavior, not just whether a policy or process exists. | E12: Practices are consistent, documented, owned by leadership or supervisors, and verified through action, follow-up, or outcomes. | F12: Scoring based on written policy only; assuming responsibility is handled elsewhere; counting infrequent or reactive actions as mature practices. | G12: Constraint: delayed reporting that prevents early medical intervention/RTW caps at 2.
A13: WC-02 | B13: WorkersComp | C13: Medical Direction (Clinics + Nurse Triage + Telemedicine) | D13: Measures whether this control actively reduces risk and influences behavior, not just whether a policy or process exists. | E13: Practices are consistent, documented, owned by leadership or supervisors, and verified through action, follow-up, or outcomes. | F13: Scoring based on written policy only; assuming responsibility is handled elsewhere; counting infrequent or reactive actions as mature practices. | G13: Constraint: if employees choose initial providers without direction, cap at 2. For remote/multi-state, no triage/telemed caps at 3.
A14: WC-03 | B14: WorkersComp | C14: Return-to-Work Execution (Transitional Duty) | D14: Measures whether this control actively reduces risk and influences behavior, not just whether a policy or process exists. | E14: Practices are consistent, documented, owned by leadership or supervisors, and verified through action, follow-up, or outcomes. | F14: Scoring based on written policy only; assuming responsibility is handled elsewhere; counting infrequent or reactive actions as mature practices. | G14: Constraint: if transitional duty not identified in advance, cap at 3. If supervisors resist restrictions, cap at 2.
A15: WC-04 | B15: WorkersComp | C15: Claim Oversight (Ownership to Closure) | D15: Measures whether this control actively reduces risk and influences behavior, not just whether a policy or process exists. | E15: Practices are consistent, documented, owned by leadership or supervisors, and verified through action, follow-up, or outcomes. | F15: Scoring based on written policy only; assuming responsibility is handled elsewhere; counting infrequent or reactive actions as mature practices. | G15: Constraint: if no specific internal role follows claims to closure, cap at 2. Renewal-only review caps at 2.
A16: WC-05 | B16: WorkersComp | C16: Claims Review Intervals (Open Claims + Trends + Action) | D16: Measures whether this control actively reduces risk and influences behavior, not just whether a policy or process exists. | E16: Practices are consistent, documented, owned by leadership or supervisors, and verified through action, follow-up, or outcomes. | F16: Scoring based on written policy only; assuming responsibility is handled elsewhere; counting infrequent or reactive actions as mature practices. | G16: Constraint: renewal-only caps at 2. If open claims not reviewed regularly to drive closure, cap at 3.
... A25: FL-08 | B25: Fleet | C25: Management Review + Accountability (Fleet) | D25: Measures whether this control actively reduces risk and influences behavior, not just whether a policy or process exists. | E25: Practices are consistent, documented, owned by leadership or supervisors, and verified through action, follow-up, or outcomes. | F25: Scoring based on written policy only; assuming responsibility is handled elsewhere; counting infrequent or reactive actions as mature practices. | G25: Constraint: if no defined cadence, cap at 2. If accountability diffused, cap at 3.

Sheet Assessment Questions
A1: Assessment Questions – Reference View
A2: Question ID | B2: Pillar | C2: Topic | D2: Full Question | E2: Weight
A4: SAF-01 | B4: Safety | C4: Policy Review & Leadership | D4: Is there a formal safety policy, how often is it reviewed, and how is executive leadership involved in supporting and enforcing safety expectations? | E4: 0.04
A5: SAF-02 | B5: Safety | C5: Training (Hire + Method + Verification) | D5: At what point do employees receive safety training, how often is it conducted, by what methods, and how is understanding or competency verified? | E5: 0.08
A6: SAF-03 | B6: Safety | C6: Incidents & Near-Misses (System Fixes) | D6: How are safety incidents and near-misses investigated, how are deficiencies in safety management systems identified, and how are those deficiencies corrected? | E6: 0.06
A7: SAF-04 | B7: Safety | C7: Supervisor Observations & Coaching (System Focus) | D7: How do supervisors conduct safety observations, provide coaching, and address system-level contributors rather than placing blame solely on employees? | E7: 0.08
A8: SAF-05 | B8: Safety | C8: Frontline Hazard Reporting (No Fear + Feedback) | D8: How do frontline employees report hazards and unsafe conditions without fear of reprisal, and how are those reports tracked, addressed, and communicated back? | E8: 0.08
A9: SAF-06 | B9: Safety | C9: Management Review & Action (Decisions + Follow-through) | D9: How does management review safety performance, what decisions are made as a result, and how is follow-through verified? | E9: 0.06
A10: WC-01 | B10: WorkersComp | C10: Injury Reporting Timeliness & Accountability | D10: How are work-related injuries reported, who is responsible for reporting, and how is timely reporting enforced to preserve medical-only and return-to-work outcomes? | E10: 0.04
A11: WC-02 | B11: WorkersComp | C11: Medical Direction (Clinics + Nurse Triage + Telemedicine) | D11: How is medical care directed following an injury, including use of nurse triage, telemedicine, and vetted occupational medical providers? | E11: 0.04
A12: WC-03 | B12: WorkersComp | C12: Return-to-Work Execution (Transitional Duty) | D12: How does the organization implement and manage return-to-work or transitional duty to reduce lost time and support recovery? | E12: 0.04
A13: WC-04 | B13: WorkersComp | C13: Claim Oversight (Ownership to Closure) | D13: Who is responsible for managing workers’ compensation claims from initial report through closure, and how is progress monitored? | E13: 0.03
A14: WC-05 | B14: WorkersComp | C14: Claims Review Intervals (Open Claims + Trends + Action) | D14: At what intervals are workers’ compensation claims reviewed, and how are open claims, trends, and corrective actions tracked? | E14: 0.03
A15: WC-06 | B15: WorkersComp | C15: Employee Trust & Check-In Cadence | D15: Who maintains contact with injured employees, how often do check-ins occur, and how is trust maintained throughout the claim? | E15: 0.02
... A23: FL-08 | B23: Fleet | C23: Management Review + Accountability (Fleet) | D23: How does leadership review fleet risk performance, assign accountability, and take action based on fleet risk metrics? | E23: 0.01

Sheet Score Interpretation
A1: Risk Score Interpretation & Action Guidance
A3: This page explains what overall and pillar scores indicate about an organization’s risk posture and provides guidance on where to focus corrective action.
A4: Score Range | B4: Rating | C4: What This Means | D4: Primary Risk Signal | E4: Recommended Focus
A6: 0–54 | B6: High Risk | C6: Controls are largely reactive or missing. Risk is unmanaged and loss severity potential is high. | D6: Lack of leading indicators, unclear ownership, delayed action. | E6: Establish basic controls, assign ownership, and implement immediate leading-indicator actions.
A7: 55–69 | B7: Elevated Risk | C7: Some controls exist but are inconsistent or poorly enforced. | D7: Paper programs without behavioral execution; gaps between policy and practice. | E7: Stabilize fundamentals, verify training and supervision, close known gaps.
A8: 70–84 | B8: Moderate Risk | C8: Core systems are in place and functioning but lack consistency or depth. | D8: Risk is managed but vulnerable to drift or localized failure. | E8: Strengthen verification, coaching, and management review cadence.
A9: 85–100 | B9: Strong / Low Risk | C9: Controls are proactive, owned, and verified. Risk is actively managed. | D9: Strong leading indicators and leadership engagement. | E9: Maintain discipline, refine based on trends, and share best practices.
A11: Pillar-Level Interpretation
A12: Pillar | B12: What a Low Score Usually Indicates | C12: Common Root Causes | D12: Priority Actions
A13: Safety / Injury Prevention | B13: Weak frontline controls and inconsistent supervision. | C13: Training gaps, blame-focused investigations, poor hazard reporting culture. | D13: Focus on supervisor engagement, frontline reporting, and system-level fixes.
A14: Workers’ Compensation Execution | B14: Delayed reporting and poor claim ownership. | C14: Unclear responsibilities, weak RTW, limited medical direction. | D14: Tighten reporting timelines, assign claim owners, and formalize RTW.
A15: Fleet Safety | B15: High exposure to catastrophic loss. | C15: Unmonitored drivers, ignored telematics data, unmanaged journey risk. | D15: Implement journey management, enforce driver qualification, act on driving data.

Sheet Narrative Generator
A1: Executive Risk Narrative Generator
A3: This narrative is auto-generated based on the assessment score and is intended for use in executive summaries, underwriting submissions, and renewal discussions.
A6: Inputs
A7: Overall Score | B7: =Summary!B8
A8: Overall Rating | B8: =Summary!B9
A9: Primary Weak Pillar (if applicable) | B9: =IFERROR(INDEX(Summary!A13:A15,MATCH(MIN(Summary!B13:B15),Summary!B13:B15,0)),"")
A11: Generated Executive Narrative
A12: =IF(B7="", "", IF(B7>=85, "Based on the results of the risk assessment, this organization demonstrates a disciplined and proactive approach to managing operational safety, workers’ compensation, and fleet exposure. Core risk controls are clearly defined, actively executed, and supported by leadership. The assessment indicates that risk management practices extend beyond written programs and are reinforced through verified training, supervisor engagement, and ongoing review of leading indicators. Overall, the organization presents as a well-managed risk with mature controls and a stable loss prevention posture suitable for favorable underwriting consideration.", IF(B7>=70, "The assessment indicates that core risk management controls are in place and functioning across safety, workers’ compensation, and fleet operations. Execution is generally consistent, with opportunities to strengthen verification and trend-based intervention. The organization demonstrates positive momentum and a commitment to continuous improvement, positioning the account as a stable risk with improving discipline and direction.", IF(B7>=55, "The assessment reflects foundational risk management programs with partial execution across operations. While policies and processes are established, consistency and follow-through vary by function or location. The organization has identified these gaps and is focused on improving supervisor engagement, strengthening leading indicators, and reinforcing accountability to enhance overall risk performance.", "The assessment identified several areas where risk controls are not yet consistently executed or verified. These gaps relate primarily to ownership clarity, timing of training and intervention, and consistency of application across operations. In response, the organization is implementing a structured improvement approach focused on strengthening leading indicators, assigning accountability, and demonstrating measurable progress over the upcoming policy period." )))
A22: =IF(B9="", "", "Primary improvement focus has been identified within the " & B9 & " pillar, where targeted actions are being implemented to improve execution, oversight, and consistency. Progress in this area is expected to strengthen overall risk performance and further support underwriting confidence.")
A30: Subcontractor Risk Narrative | B30: =IF(Subcontractor_SubScore!C3<=2,"Subcontractor insurance coverage continuity presents a material upstream risk. Active monitoring and lapse detection must be implemented to stabilize risk transfer before submission.",IF(Subcontractor_SubScore!E6>=4,"Subcontractor safety and risk transfer controls are well-integrated, reducing downstream loss volatility and improving carrier confidence.","Subcontractor safety controls are partially implemented; targeted improvements in oversight, insurance verification, or contractual alignment will strengthen the risk profile."))
A32: Action Register Summary | B32: =IFERROR("Open Actions: "&COUNTIF(Action_Register!O:O,"Open")&" | Verified: "&COUNTIF(Action_Register!O:O,"Verified")&" | Closed: "&COUNTIF(Action_Register!O:O,"Closed"),"")
A33: Action Register Exceptions | B33: =IFERROR("Blocked Closures: "&COUNTIF(Action_Register!AE:AE,"BLOCKED")&" | Validator Role Checks: "&COUNTIF(Action_Register!AF:AF,"CHECK"),"")
A34: Outcome Tracking Summary | B34: =IFERROR("Most Recent Loss Ratio: "&TEXT(LOOKUP(2,1/(Outcome_Tracking!K:K<>""),Outcome_Tracking!K:K),"0.00%")&" | Trend: "&LOOKUP(2,1/(Outcome_Tracking!M:M<>""),Outcome_Tracking!M:M),"")
A35: Execution Momentum | B35: =IFERROR("Actions Closed Since Last Checkpoint: "&LOOKUP(2,1/(Outcome_Tracking!Q:Q<>""),Outcome_Tracking!Q:Q),"")

Sheet Subcontractor_SubScore
A1: Sub-Control | B1: Description | C1: Score (1-5) | D1: Weight | E1: Weighted Score
A2: Safety Training & Oversight | B2: Subs must bring their own safety program AND comply with company rules; includes orientation, audits, enforcement. | D2: 0.3 | E2: =C2*D2
A3: Ongoing Insurance Verification | B3: Insurance verified continuously; lapses detected and escalated. | D3: 0.4 | E3: =C3*D3
A4: Coverage & Contract Integrity | B4: AI status, primary & non-contributory, indemnity alignment, exclusion review. | D4: 0.3 | E4: =C4*D4
A6: Subcontractor Sub-Score (Weighted Avg) | E6: =SUM(E2:E4)

Sheet Action_Templates
A1: Template_ID | B1: Template_Name | C1: Pillar | D1: Subscore | E1: Severity_Class | F1: Trigger_Type | G1: Trigger_Condition | H1: Required_Action | I1: Rationale | J1: Default_Priority | K1: Responsible_Role | L1: Blocking_Flag | M1: Evidence_Types_Required | N1: Minimum_Validator_Role | O1: Closure_Condition | P1: Version | Q1: Is_Active
A2: SAF-SUB-INS-001 | B2: Continuous Subcontractor Insurance Monitoring | C2: Safety | D2: Subcontractor – Insurance Continuity | E2: Financial/Legal | F2: Guardrail | G2: Insurance Continuity <= 2 | H2: Implement a process to continuously monitor subcontractor insurance coverage for policy status, renewals, and lapses throughout the duration of work. | I2: One-time insurance verification does not prevent mid-project coverage lapses, resulting in upstream uninsured exposure. | J2: Critical | K2: Insured (primary); Producer (support) | L2: YES | M2: COI monitoring log/system report; renewal tracking documentation | N2: Producer/Risk Consultant | O2: Evidence reviewed/validated; coverage confirmed current at validation | P2: 1.0 | Q2: YES
A3: SAF-SUB-TRN-001 | B3: Subcontractor Safety Program Submission & Alignment | C3: Safety | D3: Subcontractor – Training & Oversight | E3: Operational | F3: Score Threshold | G3: Training & Oversight <= 3 | H3: Require subcontractors to submit their written safety programs and confirm alignment with company safety rules prior to beginning work. | I3: Absence of verified subcontractor safety programs limits assurance of independent safety competency and increases exposure to preventable incidents. | J3: High | K3: Insured (primary); Risk Consultant (review) | L3: NO | M3: Sub safety programs; alignment review checklist | N3: Risk Consultant | O3: Evidence reviewed/validated; alignment review documented | P3: 1.0 | Q3: YES
A4: SAF-SUB-TRN-002 | B4: Site-Specific Safety Orientation | C4: Safety | D4: Subcontractor – Training & Oversight | E4: Operational | F4: Score Threshold | G4: Training & Oversight <= 3 | H4: Implement and document a site-specific safety orientation for all subcontractor personnel prior to beginning work. | I4: Site-specific hazards require documented orientation to establish expectations, authority, and enforcement standards. | J4: Medium-High | K4: Insured | L4: NO | M4: Orientation materials; attendance/sign-in records; orientation procedure | N4: Insured + Risk Consultant (review) | O4: Evidence reviewed/validated; orientation records complete | P4: 1.0 | Q4: YES
A5: SAF-SUB-CRT-001 | B5: Contractual Insurance Requirement Standardization | C5: Safety | D5: Subcontractor – Coverage & Contract Integrity | E5: Legal | F5: Score Threshold | G5: Coverage Integrity <= 3 | H5: Standardize subcontract agreements to require appropriate limits, additional insured status, and primary & non-contributory wording. | I5: Inconsistent contractual requirements weaken risk transfer and increase litigation exposure. | J5: High | K5: Insured; Legal (if applicable) | L5: NO | M5: Executed contract excerpts; insurance requirement exhibit | N5: Producer/Risk Consultant | O5: Evidence reviewed/validated; standardized language adopted | P5: 1.0 | Q5: YES
A6: SAF-SUB-CRT-002 | B6: Coverage & Endorsement Verification | C6: Safety | D6: Subcontractor – Coverage & Contract Integrity | E6: Financial/Legal | F6: Score Threshold | G6: Coverage Integrity <= 3 | H6: Verify that subcontractor insurance endorsements align with contractual requirements and do not contain material exclusions. | I6: Insurance that exists but does not respond creates false confidence and upstream exposure. | J6: High | K6: Producer/Risk Consultant (review); Insured | L6: NO | M6: Endorsement copies; coverage review checklist; exclusion review notes | N6: Producer/Risk Consultant | O6: Evidence reviewed/validated; endorsement compliance documented | P6: 1.0 | Q6: YES

Sheet Action_Register
A1: Action_ID | B1: Assessment_ID | C1: Company_Name | D1: Pillar | E1: Subscore | F1: Template_ID | G1: Template_Name | H1: Trigger_Type | I1: Trigger_Met | J1: Priority | K1: Blocking_Flag | L1: Responsible_Role | M1: Assigned_To | N1: Target_Due_Date | O1: Status | P1: Evidence_Submitted | Q1: Evidence_Link_or_Ref | R1: Validator_Role | S1: Validator_Name | T1: Validation_Status | U1: Validation_Date | V1: Validation_Notes | W1: Closed_Date | X1: Created_Date | Y1: Created_By | Z1: Last_Modified_Date | AA1: Last_Modified_By | AB1: Evidence_Types_Required | AC1: Minimum_Validator_Role | AD1: Closure_Condition | AE1: Closure_Gate | AF1: Validator_Role_Check
A2: ACT-00001 | B2: ='Company_Profile'!B5 | C2: ='Company_Profile'!B2 | D2: Safety | E2: Subcontractor – Insurance Continuity | F2: SAF-SUB-INS-001 | G2: Continuous Subcontractor Insurance Monitoring | H2: Guardrail | I2: =IF(F2="","",IFERROR(VLOOKUP(F2,Action_Generator!A:K,11,FALSE),"")) | J2: Critical | K2: YES | L2: Insured (primary); Producer (support) | O2: =IF(I2="YES","Open","") | W2: =IF(AND(O2="Closed",AE2="OK"),TODAY(),"") | X2: =TODAY() | Z2: =TODAY() | AB2: =IF(F2="","",IFERROR(VLOOKUP(F2,Action_Templates!$A:$Q,13,FALSE),"")) | AC2: =IF(F2="","",IFERROR(VLOOKUP(F2,Action_Templates!$A:$Q,14,FALSE),"")) | AD2: =IF(F2="","",IFERROR(VLOOKUP(F2,Action_Templates!$A:$Q,15,FALSE),"")) | AE2: =IF(O2="","",IF(OR(O2<>"Closed",AND(P2="YES",T2="Accepted")),"OK","BLOCKED")) | AF2: =IF(OR(AC2="",R2=""),"",IF(ISNUMBER(SEARCH(AC2,R2)),"OK","CHECK"))
A3: ACT-00002 | B3: ='Company_Profile'!B5 | C3: ='Company_Profile'!B2 | D3: Safety | E3: Subcontractor – Training & Oversight | F3: SAF-SUB-TRN-001 | G3: Subcontractor Safety Program Submission & Alignment | H3: Score Threshold | I3: =IF(F3="","",IFERROR(VLOOKUP(F3,Action_Generator!A:K,11,FALSE),"")) | J3: High | K3: NO | L3: Insured (primary); Risk Consultant (review) | O3: =IF(I3="YES","Open","") | W3: =IF(AND(O3="Closed",AE3="OK"),TODAY(),"") | X3: =TODAY() | Z3: =TODAY() | AB3: =IF(F3="","",IFERROR(VLOOKUP(F3,Action_Templates!$A:$Q,13,FALSE),"")) | AC3: =IF(F3="","",IFERROR(VLOOKUP(F3,Action_Templates!$A:$Q,14,FALSE),"")) | AD3: =IF(F3="","",IFERROR(VLOOKUP(F3,Action_Templates!$A:$Q,15,FALSE),"")) | AE3: =IF(O3="","",IF(OR(O3<>"Closed",AND(P3="YES",T3="Accepted")),"OK","BLOCKED")) | AF3: =IF(OR(AC3="",R3=""),"",IF(ISNUMBER(SEARCH(AC3,R3)),"OK","CHECK"))
A4: ACT-00003 | B4: ='Company_Profile'!B5 | C4: ='Company_Profile'!B2 | D4: Safety | E4: Subcontractor – Training & Oversight | F4: SAF-SUB-TRN-002 | G4: Site-Specific Safety Orientation | H4: Score Threshold | I4: =IF(F4="","",IFERROR(VLOOKUP(F4,Action_Generator!A:K,11,FALSE),"")) | J4: Medium-High | K4: NO | L4: Insured | O4: =IF(I4="YES","Open","") | W4: =IF(AND(O4="Closed",AE4="OK"),TODAY(),"") | X4: =TODAY() | Z4: =TODAY() | AB4: =IF(F4="","",IFERROR(VLOOKUP(F4,Action_Templates!$A:$Q,13,FALSE),"")) | AC4: =IF(F4="","",IFERROR(VLOOKUP(F4,Action_Templates!$A:$Q,14,FALSE),"")) | AD4: =IF(F4="","",IFERROR(VLOOKUP(F4,Action_Templates!$A:$Q,15,FALSE),"")) | AE4: =IF(O4="","",IF(OR(O4<>"Closed",AND(P4="YES",T4="Accepted")),"OK","BLOCKED")) | AF4: =IF(OR(AC4="",R4=""),"",IF(ISNUMBER(SEARCH(AC4,R4)),"OK","CHECK"))
A5: ACT-00004 | B5: ='Company_Profile'!B5 | C5: ='Company_Profile'!B2 | D5: Safety | E5: Subcontractor – Coverage & Contract Integrity | F5: SAF-SUB-CRT-001 | G5: Contractual Insurance Requirement Standardization | H5: Score Threshold | I5: =IF(F5="","",IFERROR(VLOOKUP(F5,Action_Generator!A:K,11,FALSE),"")) | J5: High | K5: NO | L5: Insured; Legal (if applicable) | O5: =IF(I5="YES","Open","") | W5: =IF(AND(O5="Closed",AE5="OK"),TODAY(),"") | X5: =TODAY() | Z5: =TODAY() | AB5: =IF(F5="","",IFERROR(VLOOKUP(F5,Action_Templates!$A:$Q,13,FALSE),"")) | AC5: =IF(F5="","",IFERROR(VLOOKUP(F5,Action_Templates!$A:$Q,14,FALSE),"")) | AD5: =IF(F5="","",IFERROR(VLOOKUP(F5,Action_Templates!$A:$Q,15,FALSE),"")) | AE5: =IF(O5="","",IF(OR(O5<>"Closed",AND(P5="YES",T5="Accepted")),"OK","BLOCKED")) | AF5: =IF(OR(AC5="",R5=""),"",IF(ISNUMBER(SEARCH(AC5,R5)),"OK","CHECK"))
A6: ACT-00005 | B6: ='Company_Profile'!B5 | C6: ='Company_Profile'!B2 | D6: Safety | E6: Subcontractor – Coverage & Contract Integrity | F6: SAF-SUB-CRT-002 | G6: Coverage & Endorsement Verification | H6: Score Threshold | I6: =IF(F6="","",IFERROR(VLOOKUP(F6,Action_Generator!A:K,11,FALSE),"")) | J6: High | K6: NO | L6: Producer/Risk Consultant (review); Insured | O6: =IF(I6="YES","Open","") | W6: =IF(AND(O6="Closed",AE6="OK"),TODAY(),"") | X6: =TODAY() | Z6: =TODAY() | AB6: =IF(F6="","",IFERROR(VLOOKUP(F6,Action_Templates!$A:$Q,13,FALSE),"")) | AC6: =IF(F6="","",IFERROR(VLOOKUP(F6,Action_Templates!$A:$Q,14,FALSE),"")) | AD6: =IF(F6="","",IFERROR(VLOOKUP(F6,Action_Templates!$A:$Q,15,FALSE),"")) | AE6: =IF(O6="","",IF(OR(O6<>"Closed",AND(P6="YES",T6="Accepted")),"OK","BLOCKED")) | AF6: =IF(OR(AC6="",R6=""),"",IF(ISNUMBER(SEARCH(AC6,R6)),"OK","CHECK"))
A7: ACT-00006 | B7: ='Company_Profile'!B5 | C7: ='Company_Profile'!B2 | W7: =IF(AND(O7="Closed",AE7="OK"),TODAY(),"") | AB7: =IF(F7="","",IFERROR(VLOOKUP(F7,Action_Templates!$A:$Q,13,FALSE),"")) | AC7: =IF(F7="","",IFERROR(VLOOKUP(F7,Action_Templates!$A:$Q,14,FALSE),"")) | AD7: =IF(F7="","",IFERROR(VLOOKUP(F7,Action_Templates!$A:$Q,15,FALSE),"")) | AE7: =IF(O7="","",IF(OR(O7<>"Closed",AND(P7="YES",T7="Accepted")),"OK","BLOCKED")) | AF7: =IF(OR(AC7="",R7=""),"",IF(ISNUMBER(SEARCH(AC7,R7)),"OK","CHECK"))
A8: ACT-00007 | B8: ='Company_Profile'!B5 | C8: ='Company_Profile'!B2 | W8: =IF(AND(O8="Closed",AE8="OK"),TODAY(),"") | AB8: =IF(F8="","",IFERROR(VLOOKUP(F8,Action_Templates!$A:$Q,13,FALSE),"")) | AC8: =IF(F8="","",IFERROR(VLOOKUP(F8,Action_Templates!$A:$Q,14,FALSE),"")) | AD8: =IF(F8="","",IFERROR(VLOOKUP(F8,Action_Templates!$A:$Q,15,FALSE),"")) | AE8: =IF(O8="","",IF(OR(O8<>"Closed",AND(P8="YES",T8="Accepted")),"OK","BLOCKED")) | AF8: =IF(OR(AC8="",R8=""),"",IF(ISNUMBER(SEARCH(AC8,R8)),"OK","CHECK"))
A9: ACT-00008 | B9: ='Company_Profile'!B5 | C9: ='Company_Profile'!B2 | W9: =IF(AND(O9="Closed",AE9="OK"),TODAY(),"") | AB9: =IF(F9="","",IFERROR(VLOOKUP(F9,Action_Templates!$A:$Q,13,FALSE),"")) | AC9: =IF(F9="","",IFERROR(VLOOKUP(F9,Action_Templates!$A:$Q,14,FALSE),"")) | AD9: =IF(F9="","",IFERROR(VLOOKUP(F9,Action_Templates!$A:$Q,15,FALSE),"")) | AE9: =IF(O9="","",IF(OR(O9<>"Closed",AND(P9="YES",T9="Accepted")),"OK","BLOCKED")) | AF9: =IF(OR(AC9="",R9=""),"",IF(ISNUMBER(SEARCH(AC9,R9)),"OK","CHECK"))
A10: ACT-00009 | B10: ='Company_Profile'!B5 | C10: ='Company_Profile'!B2 | W10: =IF(AND(O10="Closed",AE10="OK"),TODAY(),"") | AB10: =IF(F10="","",IFERROR(VLOOKUP(F10,Action_Templates!$A:$Q,13,FALSE),"")) | AC10: =IF(F10="","",IFERROR(VLOOKUP(F10,Action_Templates!$A:$Q,14,FALSE),"")) | AD10: =IF(F10="","",IFERROR(VLOOKUP(F10,Action_Templates!$A:$Q,15,FALSE),"")) | AE10: =IF(O10="","",IF(OR(O10<>"Closed",AND(P10="YES",T10="Accepted")),"OK","BLOCKED")) | AF10: =IF(OR(AC10="",R10=""),"",IF(ISNUMBER(SEARCH(AC10,R10)),"OK","CHECK"))
A11: ACT-00010 | B11: ='Company_Profile'!B5 | C11: ='Company_Profile'!B2 | W11: =IF(AND(O11="Closed",AE11="OK"),TODAY(),"") | AB11: =IF(F11="","",IFERROR(VLOOKUP(F11,Action_Templates!$A:$Q,13,FALSE),"")) | AC11: =IF(F11="","",IFERROR(VLOOKUP(F11,Action_Templates!$A:$Q,14,FALSE),"")) | AD11: =IF(F11="","",IFERROR(VLOOKUP(F11,Action_Templates!$A:$Q,15,FALSE),"")) | AE11: =IF(O11="","",IF(OR(O11<>"Closed",AND(P11="YES",T11="Accepted")),"OK","BLOCKED")) | AF11: =IF(OR(AC11="",R11=""),"",IF(ISNUMBER(SEARCH(AC11,R11)),"OK","CHECK"))
A12: ACT-00011 | B12: ='Company_Profile'!B5 | C12: ='Company_Profile'!B2 | W12: =IF(AND(O12="Closed",AE12="OK"),TODAY(),"") | AB12: =IF(F12="","",IFERROR(VLOOKUP(F12,Action_Templates!$A:$Q,13,FALSE),"")) | AC12: =IF(F12="","",IFERROR(VLOOKUP(F12,Action_Templates!$A:$Q,14,FALSE),"")) | AD12: =IF(F12="","",IFERROR(VLOOKUP(F12,Action_Templates!$A:$Q,15,FALSE),"")) | AE12: =IF(O12="","",IF(OR(O12<>"Closed",AND(P12="YES",T12="Accepted")),"OK","BLOCKED")) | AF12: =IF(OR(AC12="",R12=""),"",IF(ISNUMBER(SEARCH(AC12,R12)),"OK","CHECK"))
A13: ACT-00012 | B13: ='Company_Profile'!B5 | C13: ='Company_Profile'!B2 | W13: =IF(AND(O13="Closed",AE13="OK"),TODAY(),"") | AB13: =IF(F13="","",IFERROR(VLOOKUP(F13,Action_Templates!$A:$Q,13,FALSE),"")) | AC13: =IF(F13="","",IFERROR(VLOOKUP(F13,Action_Templates!$A:$Q,14,FALSE),"")) | AD13: =IF(F13="","",IFERROR(VLOOKUP(F13,Action_Templates!$A:$Q,15,FALSE),"")) | AE13: =IF(O13="","",IF(OR(O13<>"Closed",AND(P13="YES",T13="Accepted")),"OK","BLOCKED")) | AF13: =IF(OR(AC13="",R13=""),"",IF(ISNUMBER(SEARCH(AC13,R13)),"OK","CHECK"))
A14: ACT-00013 | B14: ='Company_Profile'!B5 | C14: ='Company_Profile'!B2 | W14: =IF(AND(O14="Closed",AE14="OK"),TODAY(),"") | AB14: =IF(F14="","",IFERROR(VLOOKUP(F14,Action_Templates!$A:$Q,13,FALSE),"")) | AC14: =IF(F14="","",IFERROR(VLOOKUP(F14,Action_Templates!$A:$Q,14,FALSE),"")) | AD14: =IF(F14="","",IFERROR(VLOOKUP(F14,Action_Templates!$A:$Q,15,FALSE),"")) | AE14: =IF(O14="","",IF(OR(O14<>"Closed",AND(P14="YES",T14="Accepted")),"OK","BLOCKED")) | AF14: =IF(OR(AC14="",R14=""),"",IF(ISNUMBER(SEARCH(AC14,R14)),"OK","CHECK"))
